<mujoco model="base_0">
<!-- Copyright (c) 2024 Boston Dynamics AI Institute LLC. All rights reserved. -->
  <body name="base_0" pos="0 -0.45 0" childclass="iiwa">
    <inertial mass="3.863" pos="-0.013 0 0.07" diaginertia="0.0141 0.0171 0.0178"/>
    <geom class="visual" mesh="link_0"/>
    <body name="link1_0" gravcomp="1" pos="0 0 0.1575">
      <inertial mass="2.7025" pos="0 -0.0347 0.113" diaginertia="0.0171 0.0163 0.006"/>
      <joint name="joint1_0" class="joint1"/>
      <geom class="visual" mesh="link_1"/>
      <site pos="0 0 -0.0005" name="site_link1_0"/>
      <body name="link2_0" gravcomp="1" pos="0 0 0.1830" quat="0 0 1 1">
        <inertial mass="2.7258" pos="0 0.0668 0.0344" diaginertia="0.0170 0.0162 0.0061" quat="0 0 1 1"/>
        <joint name="joint2_0" class="joint2"/>
        <geom class="visual" material="orange" mesh="link_2"/>
        <site pos="0 0 -0.01" name="site_link2_0"/>
        <body name="link3_0" gravcomp="1" pos="0 0.1845 0" quat="0 0 1 1">
          <inertial mass="3.175" pos="0 0.0296 0.1265" diaginertia="0.025 0.0238 0.0076"/>
          <joint name="joint3_0" class="joint1"/>
          <geom class="visual" mesh="link_3"/>
          <site pos="0 0 0.0355" name="site_link3_0"/>
          <body name="link4_0" gravcomp="1" pos="0 0 0.2155" quat="1 1 0 0">
            <inertial mass="2.73" pos="0 0.067 0.034" diaginertia="0.017 0.0162 0.0061" quat="1 1 0 0"/>
            <joint name="joint4_0" class="joint3"/>
            <geom class="visual" material="orange" mesh="link_4"/>
            <site pos="0 0.01 0.046" name="site_link4_0"/>
            <body name="link5_0" gravcomp="1" pos="0 0.1845 0" quat="0 0 1 1">
              <inertial mass="1.69" pos="0.0001 0.021 0.076" diaginertia="0.01 0.0087 0.00449"/>
              <joint name="joint5_0" class="joint1"/>
              <geom class="visual" mesh="link_5"/>
              <site pos="0 0 0.0335" name="site_link5_0"/>
              <body name="link6_0" gravcomp="1" pos="0 0 0.2155" quat="1 1 0 0">
                <inertial mass="1.8" pos="0 0.0026 0.0005" diaginertia="0.0051 0.0047 0.0035" quat="1 1 0 0"/>
                <joint name="joint6_0" class="joint4"/>
                <geom class="visual" pos="0 0 -0.0607" material="orange" mesh="link_6"/>
                <site pos="0 0 -0.059" name="site_link6_0"/>
                <body name="link7_0" gravcomp="1" pos="0 0.081 0" quat="0 0 1 1">
                  <inertial mass="0.4" pos="0 0 0.0294" diaginertia="0.0004 0.0004 0.0005"/>
                  <joint name="joint7_0" class="joint5"/>
                  <geom class="visual" mesh="link_7"/>
                  <geom class="visual" type="cylinder" material="gray" size="0.0315 0.0305" pos="0 0 0.0305"/>
                  <geom class="visual" type="sphere" material="orange" size="0.0315" pos="0 0 0.061"/>
                  <site pos="0 0 0.001" name="site_link7_0"/>
                </body>
              </body>
            </body>
          </body>
        </body>
      </body>
    </body>
  </body>
</mujoco>
