<mujoco model="MuJoCo Model">
  <compiler angle="radian" meshdir="../../../../../dexterity/models/meshes/" texturedir="../../../../../dexterity/models/meshes/"/>

  <option timestep="0.01" density="1" integrator="implicitfast"/>

  <default>
    <default class="visual">
      <geom type="mesh" contype="0" conaffinity="0" group="2"/>
    </default>
    <default class="collision">
      <geom group="3" priority="4" friction="0.15" rgba="1 1 1 1"/>
    </default>
    <default class="ground/main">
      <default class="ground/visual">
        <geom type="mesh" contype="0" conaffinity="0" group="2"/>
      </default>
      <default class="ground/collision">
        <geom group="3" priority="4" friction="0.15" rgba="1 1 1 1"/>
      </default>
    </default>
    <default class="spot/main">
      <default class="spot/visual">
        <geom type="mesh" contype="0" conaffinity="0" group="2"/>
      </default>
      <default class="spot/collision">
        <geom group="3" priority="4" friction="0.15" rgba="1 1 1 1"/>
      </default>
      <default class="spot/base/main">
        <default class="spot/base/visual">
          <geom type="mesh" contype="0" conaffinity="0" group="2"/>
        </default>
        <default class="spot/base/collision">
          <geom group="3" priority="4" friction="0.15" rgba="1 1 1 1"/>
        </default>
        <default class="spot/base/base">
          <joint range="-3 3" damping="30"/>
          <general ctrlrange="-3 3" forcerange="-1000 1000" biastype="affine" gainprm="300" biasprm="0 -300"/>
        </default>
      </default>
      <default class="spot/legs/main">
        <default class="spot/legs/visual">
          <geom type="mesh" contype="0" conaffinity="0" group="2"/>
        </default>
        <default class="spot/legs/collision">
          <geom group="3" priority="4" friction="0.15" rgba="1 1 1 1"/>
        </default>
        <default class="spot/legs/leg">
          <default class="spot/legs/hip_x">
            <joint range="-0.785398 0.785398"/>
          </default>
          <default class="spot/legs/hip_y">
            <joint range="-0.898845 2.29511"/>
          </default>
          <default class="spot/legs/knee">
            <joint range="-2.7929 -0.254801"/>
          </default>
        </default>
      </default>
      <default class="spot/arm/main">
        <default class="spot/arm/visual">
          <geom type="mesh" contype="0" conaffinity="0" group="2"/>
        </default>
        <default class="spot/arm/collision">
          <geom group="3" priority="4" friction="0.15" rgba="1 1 1 1"/>
        </default>
        <default class="spot/arm/arm">
          <default class="spot/arm/arm_sh0">
            <joint range="-2.61799 3.14159" damping="51"/>
          </default>
          <default class="spot/arm/arm_sh1">
            <joint range="-3.14159 0.523599" damping="76.5"/>
          </default>
          <default class="spot/arm/arm_el0">
            <joint range="0 3.14159" damping="51"/>
          </default>
          <default class="spot/arm/arm_el1">
            <joint range="-2.79253 2.79253" damping="10.2"/>
          </default>
          <default class="spot/arm/arm_wr0">
            <joint range="-1.8326 1.8326" damping="10.2"/>
          </default>
          <default class="spot/arm/arm_wr1">
            <joint range="-2.87979 2.87979" damping="10.2"/>
          </default>
          <default class="spot/arm/arm_f1x">
            <joint range="-1.57 0" damping="1.6"/>
          </default>
        </default>
      </default>
    </default>
    <default class="object/main">
      <default class="object/visual">
        <geom type="mesh" contype="0" conaffinity="0" group="2"/>
      </default>
      <default class="object/collision">
        <geom group="3" priority="4" friction="0.15" rgba="1 1 1 1"/>
      </default>
    </default>
  </default>

  <asset>
    <texture type="2d" name="bdai_texture" file="spot/bdaii_spot_wrap.png"/>
    <texture type="2d" name="ground/bdai_texture" file="spot/bdaii_spot_wrap.png"/>
    <texture type="2d" name="ground/blue_grid" builtin="checker" mark="edge" rgb1="0.2 0.3 0.4" rgb2="0.1 0.2 0.3" markrgb="0.8 0.8 0.8" width="300" height="300"/>
    <texture type="2d" name="spot/bdai_texture" file="spot/bdaii_spot_wrap.png"/>
    <texture type="2d" name="spot/blue_grid" builtin="checker" mark="edge" rgb1="0.2 0.3 0.4" rgb2="0.1 0.2 0.3" markrgb="0.8 0.8 0.8" width="300" height="300"/>
    <texture type="2d" name="spot/base/bdai_texture" file="spot/bdaii_spot_wrap.png"/>
    <texture type="2d" name="spot/base/blue_grid" builtin="checker" mark="edge" rgb1="0.2 0.3 0.4" rgb2="0.1 0.2 0.3" markrgb="0.8 0.8 0.8" width="300" height="300"/>
    <texture type="2d" name="spot/legs/bdai_texture" file="spot/bdaii_spot_wrap.png"/>
    <texture type="2d" name="spot/legs/blue_grid" builtin="checker" mark="edge" rgb1="0.2 0.3 0.4" rgb2="0.1 0.2 0.3" markrgb="0.8 0.8 0.8" width="300" height="300"/>
    <texture type="2d" name="spot/arm/bdai_texture" file="spot/bdaii_spot_wrap.png"/>
    <texture type="2d" name="spot/arm/blue_grid" builtin="checker" mark="edge" rgb1="0.2 0.3 0.4" rgb2="0.1 0.2 0.3" markrgb="0.8 0.8 0.8" width="300" height="300"/>
    <texture type="2d" name="object/bdai_texture" file="spot/bdaii_spot_wrap.png"/>
    <texture type="2d" name="object/blue_grid" builtin="checker" mark="edge" rgb1="0.2 0.3 0.4" rgb2="0.1 0.2 0.3" markrgb="0.8 0.8 0.8" width="300" height="300"/>
    <material name="black" rgba="0.2 0.2 0.2 1"/>
    <material name="yellow" rgba="1 0.8 0.03 1"/>
    <material name="bdai" texture="bdai_texture" specular="1" shininess="11"/>
    <material name="ground/black" rgba="0.2 0.2 0.2 1"/>
    <material name="ground/yellow" rgba="1 0.8 0.03 1"/>
    <material name="ground/bdai" texture="ground/bdai_texture" specular="1" shininess="11"/>
    <material name="ground/blue_grid" texture="ground/blue_grid" texuniform="true" texrepeat="5 5" reflectance="0.2"/>
    <material name="spot/black" rgba="0.2 0.2 0.2 1"/>
    <material name="spot/yellow" rgba="1 0.8 0.03 1"/>
    <material name="spot/bdai" texture="spot/bdai_texture" specular="1" shininess="11"/>
    <material name="spot/blue_grid" texture="spot/blue_grid" texuniform="true" texrepeat="5 5" reflectance="0.2"/>
    <material name="spot/base/black" rgba="0.2 0.2 0.2 1"/>
    <material name="spot/base/yellow" rgba="1 0.8 0.03 1"/>
    <material name="spot/base/bdai" texture="spot/base/bdai_texture" specular="1" shininess="11"/>
    <material name="spot/base/blue_grid" texture="spot/base/blue_grid" texuniform="true" texrepeat="5 5" reflectance="0.2"/>
    <material name="spot/legs/black" rgba="0.2 0.2 0.2 1"/>
    <material name="spot/legs/yellow" rgba="1 0.8 0.03 1"/>
    <material name="spot/legs/bdai" texture="spot/legs/bdai_texture" specular="1" shininess="11"/>
    <material name="spot/legs/blue_grid" texture="spot/legs/blue_grid" texuniform="true" texrepeat="5 5" reflectance="0.2"/>
    <material name="spot/arm/black" rgba="0.2 0.2 0.2 1"/>
    <material name="spot/arm/yellow" rgba="1 0.8 0.03 1"/>
    <material name="spot/arm/bdai" texture="spot/arm/bdai_texture" specular="1" shininess="11"/>
    <material name="spot/arm/blue_grid" texture="spot/arm/blue_grid" texuniform="true" texrepeat="5 5" reflectance="0.2"/>
    <material name="object/black" rgba="0.2 0.2 0.2 1"/>
    <material name="object/yellow" rgba="1 0.8 0.03 1"/>
    <material name="object/bdai" texture="object/bdai_texture" specular="1" shininess="11"/>
    <material name="object/blue_grid" texture="object/blue_grid" texuniform="true" texrepeat="5 5" reflectance="0.2"/>
    <mesh name="spot/base/body" file="spot/base/collision/body_collision.obj"/>
    <mesh name="spot/base/body_0_visual" file="spot/base/visual/body_0.obj"/>
    <mesh name="spot/base/body_1_visual" file="spot/base/visual/body_1.obj"/>
    <mesh name="spot/legs/left_upper_leg_collision" file="spot/base/collision/left_upper_leg_collision.obj"/>
    <mesh name="spot/legs/left_lower_leg_collision" file="spot/base/collision/left_lower_leg_collision.obj"/>
    <mesh name="spot/legs/right_upper_leg_collision" file="spot/base/collision/right_upper_leg_collision.obj"/>
    <mesh name="spot/legs/right_lower_leg_collision" file="spot/base/collision/right_lower_leg_collision.obj"/>
    <mesh name="spot/legs/front_left_hip_visual" file="spot/base/visual/front_left_hip.obj"/>
    <mesh name="spot/legs/front_left_lower_leg_visual" file="spot/base/visual/front_left_lower_leg.obj"/>
    <mesh name="spot/legs/front_left_upper_leg_0_visual" file="spot/base/visual/front_left_upper_leg_0.obj"/>
    <mesh name="spot/legs/front_left_upper_leg_1_visual" file="spot/base/visual/front_left_upper_leg_1.obj"/>
    <mesh name="spot/legs/front_right_hip_visual" file="spot/base/visual/front_right_hip.obj"/>
    <mesh name="spot/legs/front_right_lower_leg_visual" file="spot/base/visual/front_right_lower_leg.obj"/>
    <mesh name="spot/legs/front_right_upper_leg_0_visual" file="spot/base/visual/front_right_upper_leg_0.obj"/>
    <mesh name="spot/legs/front_right_upper_leg_1_visual" file="spot/base/visual/front_right_upper_leg_1.obj"/>
    <mesh name="spot/legs/rear_left_hip_visual" file="spot/base/visual/rear_left_hip.obj"/>
    <mesh name="spot/legs/rear_left_lower_leg_visual" file="spot/base/visual/rear_left_lower_leg.obj"/>
    <mesh name="spot/legs/rear_left_upper_leg_0_visual" file="spot/base/visual/rear_left_upper_leg_0.obj"/>
    <mesh name="spot/legs/rear_left_upper_leg_1_visual" file="spot/base/visual/rear_left_upper_leg_1.obj"/>
    <mesh name="spot/legs/rear_right_hip_visual" file="spot/base/visual/rear_right_hip.obj"/>
    <mesh name="spot/legs/rear_right_lower_leg_visual" file="spot/base/visual/rear_right_lower_leg.obj"/>
    <mesh name="spot/legs/rear_right_upper_leg_0_visual" file="spot/base/visual/rear_right_upper_leg_0.obj"/>
    <mesh name="spot/legs/rear_right_upper_leg_1_visual" file="spot/base/visual/rear_right_upper_leg_1.obj"/>
    <mesh name="spot/arm/arm_link_sh0_base" file="spot/arm/collision/arm_link_sh0_base.obj"/>
    <mesh name="spot/arm/arm_link_sh0_left_motor" file="spot/arm/collision/arm_link_sh0_left_motor.obj"/>
    <mesh name="spot/arm/arm_link_sh0_right_motor" file="spot/arm/collision/arm_link_sh0_right_motor.obj"/>
    <mesh name="spot/arm/arm_link_sh1" file="spot/arm/collision/arm_link_sh1.obj"/>
    <mesh name="spot/arm/arm_link_el0" file="spot/arm/collision/arm_link_el0.obj"/>
    <mesh name="spot/arm/arm_link_el1" file="spot/arm/collision/arm_link_el1_main.obj"/>
    <mesh name="spot/arm/arm_link_el1_main" file="spot/arm/collision/arm_link_el1_main.obj"/>
    <mesh name="spot/arm/arm_link_el1_lip" file="spot/arm/collision/arm_link_el1_lip.obj"/>
    <mesh name="spot/arm/arm_link_wr0" file="spot/arm/collision/arm_link_wr0.obj"/>
    <mesh name="spot/arm/arm_link_wr1" file="spot/arm/collision/arm_link_wr1.obj"/>
    <mesh name="spot/arm/left_hinge" file="spot/gripper/collision/left_hinge.obj"/>
    <mesh name="spot/arm/left_finger" file="spot/gripper/collision/left_finger.obj"/>
    <mesh name="spot/arm/left_tooth" file="spot/gripper/collision/left_tooth.obj"/>
    <mesh name="spot/arm/right_hinge" file="spot/gripper/collision/right_hinge.obj"/>
    <mesh name="spot/arm/right_finger" file="spot/gripper/collision/right_finger.obj"/>
    <mesh name="spot/arm/right_tooth" file="spot/gripper/collision/right_tooth.obj"/>
    <mesh name="spot/arm/front_jaw" file="spot/gripper/collision/front_jaw.obj"/>
    <mesh name="spot/arm/middle_jaw" file="spot/gripper/collision/middle_jaw.obj"/>
    <mesh name="spot/arm/jaw_tooth" file="spot/gripper/collision/jaw_tooth.obj"/>
    <mesh name="spot/arm/arm_link_sh0_visual" file="spot/arm/visual/arm_link_sh0.obj"/>
    <mesh name="spot/arm/arm_link_sh1_0_visual" file="spot/arm/visual/arm_link_sh1_0.obj"/>
    <mesh name="spot/arm/arm_link_sh1_1_visual" file="spot/arm/visual/arm_link_sh1_1.obj"/>
    <mesh name="spot/arm/arm_link_el0_visual" file="spot/arm/visual/arm_link_el0.obj"/>
    <mesh name="spot/arm/arm_link_el1_0_visual" file="spot/arm/visual/arm_link_el1_0.obj"/>
    <mesh name="spot/arm/arm_link_el1_1_visual" file="spot/arm/visual/arm_link_el1_1.obj"/>
    <mesh name="spot/arm/arm_link_wr0_0_visual" file="spot/arm/visual/arm_link_wr0_0.obj"/>
    <mesh name="spot/arm/arm_link_wr0_1_visual" file="spot/arm/visual/arm_link_wr0_1.obj"/>
    <mesh name="spot/arm/arm_link_wr1_0_visual" file="spot/arm/visual/arm_link_wr1_0.obj"/>
    <mesh name="spot/arm/arm_link_wr1_1_visual" file="spot/arm/visual/arm_link_wr1_1.obj"/>
    <mesh name="spot/arm/arm_link_fngr_0_visual" file="spot/gripper/visual/arm_link_fngr_0.obj"/>
    <mesh name="spot/arm/arm_link_fngr_1_visual" file="spot/gripper/visual/arm_link_fngr_1.obj"/>
  </asset>

  <worldbody>
    <body name="ground">
      <geom name="ground/ground" size="2 2 0.01" type="plane" priority="5" friction="0.8" material="ground/blue_grid"/>
    </body>
    <body name="spot">
      <inertial pos="0 0 -0.00496172" quat="0 0.707107 0 0.707107" mass="16.7077" diaginertia="0.569454 0.549231 0.0815438"/>
      <joint name="spot/base/base" type="free" limited="false" actuatorfrclimited="false"/>
      <geom name="spot/base/body_0_visual" class="spot/base/visual" material="spot/base/black" mesh="spot/base/body_0_visual"/>
      <geom name="spot/base/body_1_visual" class="spot/base/visual" material="spot/base/yellow" mesh="spot/base/body_1_visual"/>
      <geom name="spot/base/body" class="spot/base/collision" size="0.42 0.11 0.08" type="box"/>
      <site name="spot/base/site_body" pos="0 0 0.3" size="0.01"/>
      <body name="spot/legs">
        <body name="spot/legs/front_left_hip" pos="0.29785 0.055 0">
          <inertial pos="-0.0158674 0.00855842 9.03e-06" quat="-0.137996 0.694859 0.131743 0.693377" mass="1.13688" diaginertia="0.00172904 0.00166127 0.00114996"/>
          <joint name="spot/legs/joint_front_left_hip_x" class="spot/legs/hip_x" pos="0 0 0" axis="1 0 0"/>
          <geom name="spot/legs/front_left_hip_visual" class="spot/legs/visual" material="spot/legs/black" mesh="spot/legs/front_left_hip_visual"/>
          <body name="spot/legs/front_left_upper_leg" pos="0 0.110945 0">
            <inertial pos="0.00214442 -0.0111018 -0.078812" quat="0.998684 0.0454551 -0.0106253 -0.0212473" mass="2.2562" diaginertia="0.0269394 0.0260254 0.00298666"/>
            <joint name="spot/legs/joint_front_left_hip_y" class="spot/legs/hip_y" pos="0 0 0" axis="0 1 0" range="-0.898845 2.29511"/>
            <geom name="spot/legs/front_left_upper_leg_0_visual" class="spot/legs/visual" material="spot/legs/yellow" mesh="spot/legs/front_left_upper_leg_0_visual"/>
            <geom name="spot/legs/front_left_upper_leg_1_visual" class="spot/legs/visual" material="spot/legs/black" mesh="spot/legs/front_left_upper_leg_1_visual"/>
            <geom name="spot/legs/front_left_upper_leg_main" class="spot/legs/collision" size="0.05 0.165" pos="0 0 -0.13" type="capsule"/>
            <body name="spot/legs/front_left_lower_leg" pos="0.025 0 -0.3205">
              <inertial pos="0.0059736 0 -0.174664" quat="0.707099 -0.00339701 -0.00339701 0.707099" mass="0.33" diaginertia="0.00709946 0.00701419 0.000144656"/>
              <joint name="spot/legs/joint_front_left_knee" class="spot/legs/knee" pos="0 0 0" axis="0 1 0" range="-2.7929 -0.2471"/>
              <geom name="spot/legs/front_left_lower_leg_visual" class="spot/legs/visual" material="spot/legs/black" mesh="spot/legs/front_left_lower_leg_visual"/>
              <geom name="spot/legs/front_left_lower_leg_main" class="spot/legs/collision" size="0.03 0.15" pos="0 0 -0.155" type="capsule"/>
              <geom name="spot/legs/front_left_foot" class="spot/legs/collision" size="0.036" pos="0 0 -0.3365"/>
              <site name="spot/legs/site_front_left" pos="0 0 -0.3365" size="0.01"/>
            </body>
          </body>
        </body>
        <body name="spot/legs/front_right_hip" pos="0.29785 -0.055 0">
          <inertial pos="-0.0158674 -0.00855842 9.03e-06" quat="0.137996 0.694859 -0.131743 0.693377" mass="1.13688" diaginertia="0.00172904 0.00166127 0.00114996"/>
          <joint name="spot/legs/joint_front_right_hip_x" class="spot/legs/hip_x" pos="0 0 0" axis="1 0 0"/>
          <geom name="spot/legs/front_right_hip_visual" class="spot/legs/visual" material="spot/legs/black" mesh="spot/legs/front_right_hip_visual"/>
          <body name="spot/legs/front_right_upper_leg" pos="0 -0.110945 0">
            <inertial pos="0.00214442 0.0111018 -0.078812" quat="0.998684 -0.0454551 -0.0106253 0.0212473" mass="2.2562" diaginertia="0.0269394 0.0260254 0.00298666"/>
            <joint name="spot/legs/joint_front_right_hip_y" class="spot/legs/hip_y" pos="0 0 0" axis="0 1 0" range="-0.898845 2.29511"/>
            <geom name="spot/legs/front_right_upper_leg_0_visual" class="spot/legs/visual" material="spot/legs/yellow" mesh="spot/legs/front_right_upper_leg_0_visual"/>
            <geom name="spot/legs/front_right_upper_leg_1_visual" class="spot/legs/visual" material="spot/legs/black" mesh="spot/legs/front_right_upper_leg_1_visual"/>
            <geom name="spot/legs/front_right_upper_leg_main" class="spot/legs/collision" size="0.05 0.165" pos="0 0 -0.13" type="capsule"/>
            <body name="spot/legs/front_right_lower_leg" pos="0.025 0 -0.3205">
              <inertial pos="0.0059736 0 -0.174664" quat="0.707099 -0.00339701 -0.00339701 0.707099" mass="0.33" diaginertia="0.00709946 0.00701419 0.000144656"/>
              <joint name="spot/legs/joint_front_right_knee" class="spot/legs/knee" pos="0 0 0" axis="0 1 0" range="-2.7929 -0.2471"/>
              <geom name="spot/legs/front_right_lower_leg_visual" class="spot/legs/visual" material="spot/legs/black" mesh="spot/legs/front_right_lower_leg_visual"/>
              <geom name="spot/legs/front_right_lower_leg_main" class="spot/legs/collision" size="0.03 0.15" pos="0 0 -0.155" type="capsule"/>
              <geom name="spot/legs/front_right_foot" class="spot/legs/collision" size="0.036" pos="0 0 -0.3365"/>
              <site name="spot/legs/site_front_right" pos="0 0 -0.3365" size="0.01"/>
            </body>
          </body>
        </body>
        <body name="spot/legs/rear_left_hip" pos="-0.29785 0.055 0">
          <inertial pos="0.0158674 0.00855842 9.03e-06" quat="0.131743 0.693377 -0.137996 0.694859" mass="1.13688" diaginertia="0.00172904 0.00166127 0.00114996"/>
          <joint name="spot/legs/joint_rear_left_hip_x" class="spot/legs/hip_x" pos="0 0 0" axis="1 0 0"/>
          <geom name="spot/legs/rear_left_hip_visual" class="spot/legs/visual" material="spot/legs/black" mesh="spot/legs/rear_left_hip_visual"/>
          <body name="spot/legs/rear_left_upper_leg" pos="0 0.110945 0">
            <inertial pos="0.00214442 -0.0111018 -0.078812" quat="0.998684 0.0454551 -0.0106253 -0.0212473" mass="2.2562" diaginertia="0.0269394 0.0260254 0.00298666"/>
            <joint name="spot/legs/joint_rear_left_hip_y" class="spot/legs/hip_y" pos="0 0 0" axis="0 1 0" range="-0.898845 2.29511"/>
            <geom name="spot/legs/rear_left_upper_leg_0_visual" class="spot/legs/visual" material="spot/legs/yellow" mesh="spot/legs/rear_left_upper_leg_0_visual"/>
            <geom name="spot/legs/rear_left_upper_leg_1_visual" class="spot/legs/visual" material="spot/legs/black" mesh="spot/legs/rear_left_upper_leg_1_visual"/>
            <geom name="spot/legs/rear_left_upper_leg_main" class="spot/legs/collision" size="0.05 0.165" pos="0 0 -0.13" type="capsule"/>
            <body name="spot/legs/rear_left_lower_leg" pos="0.025 0 -0.3205">
              <inertial pos="0.0059736 0 -0.174664" quat="0.707099 -0.00339701 -0.00339701 0.707099" mass="0.33" diaginertia="0.00709946 0.00701419 0.000144656"/>
              <joint name="spot/legs/joint_rear_left_knee" class="spot/legs/knee" pos="0 0 0" axis="0 1 0" range="-2.7929 -0.2471"/>
              <geom name="spot/legs/rear_left_lower_leg_visual" class="spot/legs/visual" material="spot/legs/black" mesh="spot/legs/rear_left_lower_leg_visual"/>
              <geom name="spot/legs/rear_left_lower_leg_main" class="spot/legs/collision" size="0.03 0.15" pos="0 0 -0.155" type="capsule"/>
              <geom name="spot/legs/rear_left_foot" class="spot/legs/collision" size="0.036" pos="0 0 -0.3365"/>
              <site name="spot/legs/site_rear_left" pos="0 0 -0.3365" size="0.01"/>
            </body>
          </body>
        </body>
        <body name="spot/legs/rear_right_hip" pos="-0.29785 -0.055 0">
          <inertial pos="0.0158674 -0.00855842 9.03e-06" quat="-0.131743 0.693377 0.137996 0.694859" mass="1.13688" diaginertia="0.00172904 0.00166127 0.00114996"/>
          <joint name="spot/legs/joint_rear_right_hip_x" class="spot/legs/hip_x" pos="0 0 0" axis="1 0 0"/>
          <geom name="spot/legs/rear_right_hip_visual" class="spot/legs/visual" material="spot/legs/black" mesh="spot/legs/rear_right_hip_visual"/>
          <body name="spot/legs/rear_right_upper_leg" pos="0 -0.110945 0">
            <inertial pos="0.00214442 0.0111018 -0.078812" quat="0.998684 -0.0454551 -0.0106253 0.0212473" mass="2.2562" diaginertia="0.0269394 0.0260254 0.00298666"/>
            <joint name="spot/legs/joint_rear_right_hip_y" class="spot/legs/hip_y" pos="0 0 0" axis="0 1 0" range="-0.898845 2.29511"/>
            <geom name="spot/legs/rear_right_upper_leg_0_visual" class="spot/legs/visual" material="spot/legs/yellow" mesh="spot/legs/rear_right_upper_leg_0_visual"/>
            <geom name="spot/legs/rear_right_upper_leg_1_visual" class="spot/legs/visual" material="spot/legs/black" mesh="spot/legs/rear_right_upper_leg_1_visual"/>
            <geom name="spot/legs/rear_right_upper_leg_main" class="spot/legs/collision" size="0.05 0.165" pos="0 0 -0.13" type="capsule"/>
            <body name="spot/legs/rear_right_lower_leg" pos="0.025 0 -0.3205">
              <inertial pos="0.0059736 0 -0.174664" quat="0.707099 -0.00339701 -0.00339701 0.707099" mass="0.33" diaginertia="0.00709946 0.00701419 0.000144656"/>
              <joint name="spot/legs/joint_rear_right_knee" class="spot/legs/knee" pos="0 0 0" axis="0 1 0" range="-2.7929 -0.2471"/>
              <geom name="spot/legs/rear_right_lower_leg_visual" class="spot/legs/visual" material="spot/legs/black" mesh="spot/legs/rear_right_lower_leg_visual"/>
              <geom name="spot/legs/rear_right_lower_leg_main" class="spot/legs/collision" size="0.03 0.15" pos="0 0 -0.155" type="capsule"/>
              <geom name="spot/legs/rear_right_foot" class="spot/legs/collision" size="0.036" pos="0 0 -0.3365"/>
              <site name="spot/legs/site_rear_right" pos="0 0 -0.3365" size="0.01"/>
            </body>
          </body>
        </body>
      </body>
      <body name="spot/arm">
        <body name="spot/arm/arm_link_sh0" pos="0.292 0 0.188" gravcomp="1">
          <inertial pos="-0.008399 0.000272 -0.024603" quat="0.710827 0.700855 0.0423863 -0.0416066" mass="1.9047" diaginertia="0.00891905 0.00728042 0.00492153"/>
          <joint name="spot/arm/arm_sh0" class="spot/arm/arm_sh0" pos="0 0 0" axis="0 0 1"/>
          <geom name="spot/arm/arm_link_sh0_visual" class="spot/arm/visual" material="spot/arm/black" mesh="spot/arm/arm_link_sh0_visual"/>
          <geom name="spot/arm/arm_link_sh0_base" class="spot/arm/collision" size="0.05 0.015" pos="0 0 -0.07" type="capsule"/>
          <geom name="spot/arm/arm_link_sh0_motor" class="spot/arm/collision" size="0.055 0.055" pos="-0.015 0 0" quat="0.707107 0.707107 0 0" type="capsule"/>
          <site name="spot/arm/site_arm_link_sh0" pos="0 0 0" size="0.01"/>
          <body name="spot/arm/arm_link_sh1" gravcomp="1">
            <inertial pos="0.0808491 -0.00167243 0.00045644" quat="-0.00467017 0.708456 0.00702831 0.705705" mass="1.85702" diaginertia="0.0281997 0.0270454 0.00260818"/>
            <joint name="spot/arm/arm_sh1" class="spot/arm/arm_sh1" pos="0 0 0" axis="0 1 0"/>
            <geom name="spot/arm/arm_link_sh1_0_visual" class="spot/arm/visual" material="spot/arm/yellow" mesh="spot/arm/arm_link_sh1_0_visual"/>
            <geom name="spot/arm/arm_link_sh1_1_visual" class="spot/arm/visual" material="spot/arm/black" mesh="spot/arm/arm_link_sh1_1_visual"/>
            <geom name="spot/arm/arm_link_sh1" class="spot/arm/collision" size="0.04 0.175" pos="0.17 0 0" quat="0.707107 0 0.707107 0" type="capsule"/>
            <site name="spot/arm/site_arm_link_sh1" pos="0 0 0" size="0.01"/>
            <body name="spot/arm/arm_link_el0" pos="0.3385 0 0" gravcomp="1">
              <inertial pos="0.0447662 -0.0027113 0.0499136" quat="0.0923782 0.888458 0.19384 0.40563" mass="0.94832" diaginertia="0.00286401 0.00265579 0.000960161"/>
              <joint name="spot/arm/arm_el0" class="spot/arm/arm_el0" pos="0 0 0" axis="0 1 0"/>
              <geom name="spot/arm/arm_link_el0_visual" class="spot/arm/visual" material="spot/arm/black" mesh="spot/arm/arm_link_el0_visual"/>
              <geom name="spot/arm/arm_link_el0_joint" class="spot/arm/collision" size="0.025 0.045 0.065" pos="0.02 0 0.04" quat="0.968912 0 0.247404 0" type="box"/>
              <geom name="spot/arm/arm_link_el0_body" class="spot/arm/collision" size="0.045 0.025" pos="0.08 0 0.07" quat="0.707107 0 0.707107 0" type="capsule"/>
              <site name="spot/arm/site_arm_link_el0" pos="0 0 0" size="0.01"/>
              <body name="spot/arm/arm_link_el1" pos="0.4033 0 0.075" gravcomp="1">
                <inertial pos="-0.168671 -0.0161612 1.149e-05" quat="0.488034 0.425158 0.565043 0.511654" mass="1.01755" diaginertia="0.0169253 0.0168986 0.000746021"/>
                <joint name="spot/arm/arm_el1" class="spot/arm/arm_el1" pos="0 0 0" axis="1 0 0"/>
                <geom name="spot/arm/arm_link_el1_0_visual" class="spot/arm/visual" material="spot/arm/yellow" mesh="spot/arm/arm_link_el1_0_visual"/>
                <geom name="spot/arm/arm_link_el1_1_visual" class="spot/arm/visual" material="spot/arm/black" mesh="spot/arm/arm_link_el1_1_visual"/>
                <geom name="spot/arm/arm_link_el1" class="spot/arm/collision" size="0.035 0.095" pos="-0.15 0 0" quat="0.707107 0 0.707107 0" type="capsule"/>
                <geom name="spot/arm/arm_link_el1_knob" class="spot/arm/collision" size="0.04" pos="0 -0.035 0"/>
                <site name="spot/arm/site_arm_link_el1" pos="0 0 0" size="0.01"/>
                <body name="spot/arm/arm_link_wr0" gravcomp="1">
                  <inertial pos="0.00952465 -0.0114441 1.86e-06" quat="0.308237 0.652328 -0.273781 0.636005" mass="0.582637" diaginertia="0.000536182 0.000528639 0.000388399"/>
                  <joint name="spot/arm/arm_wr0" class="spot/arm/arm_wr0" pos="0 0 0" axis="0 1 0"/>
                  <geom name="spot/arm/arm_link_wr0_0_visual" class="spot/arm/visual" material="spot/arm/yellow" mesh="spot/arm/arm_link_wr0_0_visual"/>
                  <geom name="spot/arm/arm_link_wr0_1_visual" class="spot/arm/visual" material="spot/arm/black" mesh="spot/arm/arm_link_wr0_1_visual"/>
                  <geom name="spot/arm/arm_link_wr0" class="spot/arm/collision" size="0.035 0.04" pos="0.02 0 0" quat="0.707107 0 0.707107 0" type="capsule"/>
                  <site name="spot/arm/site_arm_link_wr0" pos="0 0 0" size="0.01"/>
                  <body name="spot/arm/arm_link_wr1" gravcomp="1">
                    <inertial pos="0.0975128 9.265e-05 -0.0112052" quat="0.592778 0.385047 0.386229 0.592605" mass="0.933353" diaginertia="0.00197018 0.00182151 0.00082476"/>
                    <joint name="spot/arm/arm_wr1" class="spot/arm/arm_wr1" pos="0 0 0" axis="1 0 0"/>
                    <geom name="spot/arm/arm_link_wr1_0_visual" class="spot/arm/visual" material="spot/arm/yellow" mesh="spot/arm/arm_link_wr1_0_visual"/>
                    <geom name="spot/arm/arm_link_wr1_1_visual" class="spot/arm/visual" material="spot/arm/black" mesh="spot/arm/arm_link_wr1_1_visual"/>
                    <geom name="spot/arm/arm_link_wr1" class="spot/arm/collision" size="0.03 0.04 0.0475" pos="0.11 0 -0.01" type="box"/>
                    <geom name="spot/arm/bottom_jaw" class="spot/arm/collision" size="0.03 0.025 0.01" pos="0.17 0 -0.0475" type="box"/>
                    <geom name="spot/arm/front_jaw" class="spot/arm/collision" size="0.016 0.015 0.01" pos="0.215 0 -0.0475" type="box"/>
                    <geom name="spot/arm/front_jaw_tooth" class="spot/arm/collision" size="0.005 0.01 0.005" pos="0.224 0 -0.039" quat="0.877583 0 0.479426 0" type="box"/>
                    <site name="spot/arm/site_arm_link_wr1" pos="0 0 0" size="0.01"/>
                    <body name="spot/arm/arm_link_fngr" pos="0.11745 0 0.01482" gravcomp="1">
                      <inertial pos="0.0356518 0.000672 -0.0122752" quat="0.00481109 0.567709 0.0124565 0.823121" mass="0.223833" diaginertia="0.000648792 0.000484516 0.000194933"/>
                      <joint name="spot/arm/arm_f1x" class="spot/arm/arm_f1x" pos="0 0 0" axis="0 1 0"/>
                      <geom name="spot/arm/arm_link_fngr_0_visual" class="spot/arm/visual" material="spot/arm/yellow" mesh="spot/arm/arm_link_fngr_0_visual"/>
                      <geom name="spot/arm/arm_link_fngr_1_visual" class="spot/arm/visual" material="spot/arm/black" mesh="spot/arm/arm_link_fngr_1_visual"/>
                      <geom name="spot/arm/left_jaw" class="spot/arm/collision" size="0.015 0.06" pos="0.057 0.023 -0.023" quat="0.526684 -0.120545 0.820261 -0.187738" type="capsule"/>
                      <geom name="spot/arm/right_jaw" class="spot/arm/collision" size="0.015 0.06" pos="0.057 -0.023 -0.023" quat="0.526684 0.120545 0.820261 0.187738" type="capsule"/>
                      <site name="spot/arm/site_arm_link_fngr" pos="0 0 0" size="0.01"/>
                    </body>
                  </body>
                </body>
              </body>
            </body>
          </body>
        </body>
      </body>
    </body>
    <body name="object" pos="0 0 0.275">
      <inertial pos="0 0 0" mass="1.5" diaginertia="0.01 0.01 0.01"/>
      <joint name="object/box_joint" type="free" limited="false" actuatorfrclimited="false"/>
      <geom name="object/box" class="object/collision" size="0.275 0.275 0.275" type="box"/>
      <geom name="object/visual_box" class="object/visual" size="0.275 0.275 0.275" type="box"/>
      <site name="object/site_object" pos="0 0 0" size="0.01"/>
    </body>
  </worldbody>

  <contact>
    <exclude body1="spot" body2="spot/legs/front_left_upper_leg"/>
    <exclude body1="spot" body2="spot/legs/front_right_upper_leg"/>
    <exclude body1="spot" body2="spot/legs/rear_left_upper_leg"/>
    <exclude body1="spot" body2="spot/legs/rear_right_upper_leg"/>
    <exclude body1="spot/arm/arm_link_sh0" body2="spot/arm/arm_link_el1"/>
    <exclude body1="spot/arm/arm_link_sh1" body2="spot/arm/arm_link_el0"/>
    <exclude body1="spot/arm/arm_link_sh1" body2="spot/arm/arm_link_el1"/>
  </contact>

  <actuator>
    <general name="spot/legs/act_fl1" joint="spot/legs/joint_front_left_hip_x" ctrlrange="-0.785398 0.785398" forcerange="-45 45" biastype="affine" gainprm="60" biasprm="0 -60 -1.5"/>
    <general name="spot/legs/act_fl2" joint="spot/legs/joint_front_left_hip_y" ctrlrange="-0.898845 2.29511" forcerange="-45 45" biastype="affine" gainprm="60" biasprm="0 -60 -1.5"/>
    <general name="spot/legs/act_fl3" joint="spot/legs/joint_front_left_knee" ctrlrange="-2.7929 -0.254801" forcerange="-115 115" biastype="affine" gainprm="60" biasprm="0 -60 -1.5"/>
    <general name="spot/legs/act_fr1" joint="spot/legs/joint_front_right_hip_x" ctrlrange="-0.785398 0.785398" forcerange="-45 45" biastype="affine" gainprm="60" biasprm="0 -60 -1.5"/>
    <general name="spot/legs/act_fr2" joint="spot/legs/joint_front_right_hip_y" ctrlrange="-0.898845 2.29511" forcerange="-45 45" biastype="affine" gainprm="60" biasprm="0 -60 -1.5"/>
    <general name="spot/legs/act_fr3" joint="spot/legs/joint_front_right_knee" ctrlrange="-2.7929 -0.254801" forcerange="-115 115" biastype="affine" gainprm="60" biasprm="0 -60 -1.5"/>
    <general name="spot/legs/act_rl1" joint="spot/legs/joint_rear_left_hip_x" ctrlrange="-0.785398 0.785398" forcerange="-45 45" biastype="affine" gainprm="60" biasprm="0 -60 -1.5"/>
    <general name="spot/legs/act_rl2" joint="spot/legs/joint_rear_left_hip_y" ctrlrange="-0.898845 2.29511" forcerange="-45 45" biastype="affine" gainprm="60" biasprm="0 -60 -1.5"/>
    <general name="spot/legs/act_rl3" joint="spot/legs/joint_rear_left_knee" ctrlrange="-2.7929 -0.254801" forcerange="-115 115" biastype="affine" gainprm="60" biasprm="0 -60 -1.5"/>
    <general name="spot/legs/act_rr1" joint="spot/legs/joint_rear_right_hip_x" ctrlrange="-0.785398 0.785398" forcerange="-45 45" biastype="affine" gainprm="60" biasprm="0 -60 -1.5"/>
    <general name="spot/legs/act_rr2" joint="spot/legs/joint_rear_right_hip_y" ctrlrange="-0.898845 2.29511" forcerange="-45 45" biastype="affine" gainprm="60" biasprm="0 -60 -1.5"/>
    <general name="spot/legs/act_rr3" joint="spot/legs/joint_rear_right_knee" ctrlrange="-2.7929 -0.254801" forcerange="-115 115" biastype="affine" gainprm="60" biasprm="0 -60 -1.5"/>
    <general name="spot/arm/act_3" joint="spot/arm/arm_sh0" ctrlrange="-2.61799 3.14159" forcerange="-90.9 90" biastype="affine" gainprm="1020" biasprm="0 -1020"/>
    <general name="spot/arm/act_4" joint="spot/arm/arm_sh1" ctrlrange="-3.14159 0.523599" forcerange="-181.8 181.8" biastype="affine" gainprm="255" biasprm="0 -255"/>
    <general name="spot/arm/act_5" joint="spot/arm/arm_el0" ctrlrange="0 3.14159" forcerange="-90.9 90" biastype="affine" gainprm="204" biasprm="0 -204"/>
    <general name="spot/arm/act_6" joint="spot/arm/arm_el1" ctrlrange="-2.79253 2.79253" forcerange="-30.3 30.3" biastype="affine" gainprm="102" biasprm="0 -102"/>
    <general name="spot/arm/act_7" joint="spot/arm/arm_wr0" ctrlrange="-1.8326 1.8326" forcerange="-30.9 30" biastype="affine" gainprm="102" biasprm="0 -102"/>
    <general name="spot/arm/act_8" joint="spot/arm/arm_wr1" ctrlrange="-2.87979 2.87979" forcerange="-30.9 30" biastype="affine" gainprm="102" biasprm="0 -102"/>
    <general name="spot/arm/act_9" joint="spot/arm/arm_f1x" ctrlrange="-1.57 0" forcerange="-15.32 15.32" biastype="affine" gainprm="16" biasprm="0 -16"/>
  </actuator>

  <sensor>
    <framepos objtype="site" objname="spot/base/site_body" reftype="site" refname="object/site_object" name="scene_sensor_body"/>
    <frameyaxis objtype="site" objname="object/site_object" name="scene_sensor_object_y_axis"/>
    <framepos objtype="site" objname="spot/arm/site_arm_link_fngr" reftype="site" refname="object/site_object" name="scene_sensor_fngr_obj"/>
    <framepos objtype="site" objname="spot/base/site_body" name="scene_trace_body"/>
    <framepos objtype="site" objname="spot/arm/site_arm_link_fngr" name="scene_trace_gripper"/>
  </sensor>
</mujoco>
