<!-- Copyright (c) 2024 Boston Dynamics AI Institute LLC. All rights reserved. -->
<sdf version="1.7">
  <model name="spot_arm">
    <link name="arm_body_link">
      <pose>-0.292 -0 -0.188 0 0 0</pose>
    </link>

    <link name="arm_link_sh0">
      <!-- <pose>0.292 0 0.188 0 0 0</pose> -->
      <inertial>
        <mass>1</mass>
        <inertia>
          <ixx>0.05</ixx>
          <ixy>0</ixy>
          <ixz>0</ixz>
          <iyy>0.05</iyy>
          <iyz>0</iyz>
          <izz>0.05</izz>
        </inertia>
      </inertial>
      <visual name="arm_link_sh0_visual">
        <geometry>
          <mesh>
            <scale>1 1 1</scale>
            <uri>package://spot_data/arm/visual/arm_link_sh0.obj</uri>
          </mesh>
        </geometry>
      </visual>
      <collision name="arm_link_sh0_base">
        <geometry>
          <mesh>
            <scale>1 1 1</scale>
            <uri>package://spot_data/arm/collision/arm_link_sh0_base.obj</uri>
          </mesh>
        </geometry>
      </collision>
      <collision name="arm_link_sh0_left_motor">
        <geometry>
          <mesh>
            <scale>1 1 1</scale>
            <uri>package://spot_data/arm/collision/arm_link_sh0_left_motor.obj</uri>
          </mesh>
        </geometry>
      </collision>
      <collision name="arm_link_sh0_right_motor">
        <geometry>
          <mesh>
            <scale>1 1 1</scale>
            <uri>package://spot_data/arm/collision/arm_link_sh0_right_motor.obj</uri>
          </mesh>
        </geometry>
      </collision>
    </link>
    <joint name="arm_sh0" type="revolute">
      <parent>arm_body_link</parent>
      <child>arm_link_sh0</child>
      <axis>
        <xyz>0 0 1</xyz>
        <dynamics>
	        <damping>0.001</damping>
        </dynamics>
      </axis>
    </joint>


    <link name="arm_link_sh1">
      <pose>0 0 0 0 0 0</pose>
      <inertial>
        <mass>1</mass>
        <inertia>
          <ixx>0.05</ixx>
          <ixy>0</ixy>
          <ixz>0</ixz>
          <iyy>0.05</iyy>
          <iyz>0</iyz>
          <izz>0.05</izz>
        </inertia>
      </inertial>
      <visual name="arm_link_sh1_visual">
        <geometry>
          <mesh>
            <scale>1 1 1</scale>
            <uri>package://spot_data/arm/visual/arm_link_sh1.obj</uri>
          </mesh>
        </geometry>
      </visual>
    </link>
    <joint name="arm_sh1" type="revolute">
      <parent>arm_link_sh0</parent>
      <child>arm_link_sh1</child>
      <axis>
        <xyz>0 1 0</xyz>
        <dynamics>
	        <damping>0.001</damping>
        </dynamics>
      </axis>
    </joint>


    <link name="arm_link_el0">
      <pose>0.3385 0 0 0 0 0</pose>
      <inertial>
        <mass>1</mass>
        <inertia>
          <ixx>0.05</ixx>
          <ixy>0</ixy>
          <ixz>0</ixz>
          <iyy>0.05</iyy>
          <iyz>0</iyz>
          <izz>0.05</izz>
        </inertia>
      </inertial>
      <visual name="arm_link_el0_visual">
        <geometry>
          <mesh>
            <scale>1 1 1</scale>
            <uri>package://spot_data/arm/visual/arm_link_el0.obj</uri>
          </mesh>
        </geometry>
      </visual>
    </link>
    <joint name="arm_el0" type="revolute">
      <parent>arm_link_sh1</parent>
      <child>arm_link_el0</child>
      <axis>
        <xyz>0 1 0</xyz>
        <dynamics>
	        <damping>0.001</damping>
        </dynamics>
      </axis>
    </joint>


    <link name="arm_link_el1">
      <!-- <pose>0.40330+0.3385 0.0 0.0750 0 0 0</pose> -->
      <pose>0.7418 0.0 0.0750 0 0 0</pose>
      <inertial>
        <mass>1</mass>
        <inertia>
          <ixx>0.05</ixx>
          <ixy>0</ixy>
          <ixz>0</ixz>
          <iyy>0.05</iyy>
          <iyz>0</iyz>
          <izz>0.05</izz>
        </inertia>
      </inertial>
      <visual name="arm_link_el1_visual">
        <geometry>
          <mesh>
            <scale>1 1 1</scale>
            <uri>package://spot_data/arm/visual/arm_link_el1.obj</uri>
          </mesh>
        </geometry>
      </visual>
    </link>
    <joint name="arm_el1" type="revolute">
      <parent>arm_link_el0</parent>
      <child>arm_link_el1</child>
      <axis>
        <xyz>1 0 0</xyz>
        <dynamics>
	        <damping>0.001</damping>
        </dynamics>
      </axis>
    </joint>


    <link name="arm_link_wr0">
      <!-- <pose>0.40330+0.3385 0.0 0.0750 0 0 0</pose> -->
      <pose>0.7418 0.0 0.0750 0 0 0</pose>
      <inertial>
        <mass>1</mass>
        <inertia>
          <ixx>0.05</ixx>
          <ixy>0</ixy>
          <ixz>0</ixz>
          <iyy>0.05</iyy>
          <iyz>0</iyz>
          <izz>0.05</izz>
        </inertia>
      </inertial>
      <visual name="arm_link_wr0_visual">
        <geometry>
          <mesh>
            <scale>1 1 1</scale>
            <uri>package://spot_data/arm/visual/arm_link_wr0.obj</uri>
          </mesh>
        </geometry>
      </visual>
    </link>
    <joint name="arm_wr0" type="revolute">
      <parent>arm_link_el1</parent>
      <child>arm_link_wr0</child>
      <axis>
        <xyz> 0 1 0</xyz>
        <dynamics>
	        <damping>0.001</damping>
        </dynamics>
      </axis>
    </joint>


    <link name="arm_link_wr1">
      <!-- <pose>0.40330+0.3385 0.0 0.0750 0 0 0</pose> -->
      <pose>0.7418 0.0 0.0750 0 0 0</pose>
      <inertial>
        <mass>1</mass>
        <inertia>
          <ixx>0.05</ixx>
          <ixy>0</ixy>
          <ixz>0</ixz>
          <iyy>0.05</iyy>
          <iyz>0</iyz>
          <izz>0.05</izz>
        </inertia>
      </inertial>
      <visual name="arm_link_wr1_visual">
        <geometry>
          <mesh>
            <scale>1 1 1</scale>
            <uri>package://spot_data/arm/visual/arm_link_wr1.obj</uri>
          </mesh>
        </geometry>
      </visual>
    </link>
    <joint name="arm_wr1" type="revolute">
      <parent>arm_link_wr0</parent>
      <child>arm_link_wr1</child>
      <axis>
        <xyz>1 0 0</xyz>
        <dynamics>
	        <damping>0.001</damping>
        </dynamics>
      </axis>
    </joint>

  </model>
</sdf>
