<!-- Copyright (c) 2024 Boston Dynamics AI Institute LLC. All rights reserved. -->
<sdf version="1.7">
  <model name="spot_gripper">
    <link name="arm_link_wr1">
    </link>

    <link name="arm_link_fngr">
      <pose>0.1174 0.0 0.0148 0 0 0</pose>
      <inertial>
        <mass>1</mass>
        <inertia>
          <ixx>0.05</ixx>
          <ixy>0</ixy>
          <ixz>0</ixz>
          <iyy>0.05</iyy>
          <iyz>0</iyz>
          <izz>0.05</izz>
        </inertia>
      </inertial>
      <visual name="arm_link_fngr_visual">
        <geometry>
          <mesh>
            <scale>1 1 1</scale>
            <uri>package://spot_data/gripper/visual/arm_link_fngr.obj</uri>
          </mesh>
        </geometry>
      </visual>
    </link>
    <joint name="arm_f1x" type="revolute">
      <parent>arm_link_wr1</parent>
      <child>arm_link_fngr</child>
      <axis>
        <xyz>0 1 0</xyz>
        <dynamics>
	        <damping>0.001</damping>
        </dynamics>
      </axis>
    </joint>

  </model>
</sdf>
