<mujoco model="planar_hand">
<!-- Copyright (c) 2023 Boston Dynamics AI Institute LLC. All rights reserved. -->
  <compiler angle="radian" autolimits="true"/>
  <option gravity="0 0 -9.81" timestep="0.01" />
  <asset>
    <texture name="blue_grid" type="2d" builtin="checker" rgb1=".02 .14 .44" rgb2=".27 .55 1" width="300" height="300" mark="edge" markrgb="1 1 1"/>
    <material name="blue_grid" texture="blue_grid" texrepeat="1 1" texuniform="true" reflectance=".2"/>
    <material name="object" rgba="0.6 0.9 1 1"/>
    <material name="grey" rgba="0.75 .75 .75 1"/>
    <material name="black" rgba="0.1 .1 .1 1"/>
  </asset>

  <default>
    <material specular="0.5" shininess="0.95"/>
    <!-- <geom margin="10.0" gap="10.0"/> -->
    <default class="finger">
      <joint axis="0 1 0" damping="2"/>
      <position kp="25" forcerange="-1000 1000"/>
      <default class="left_shoulder">
        <joint range="-1.57 0"/>
        <position ctrlrange="-1.57 0"/>
      </default>
      <default class="right_shoulder">
        <joint range="0 1.57"/>
        <position ctrlrange="0 1.57"/>
      </default>
      <default class="left_elbow">
        <joint range="-2.4 0"/>
        <position ctrlrange="-2.4 0"/>
      </default>
      <default class="right_elbow">
        <joint range="0 2.4"/>
        <position ctrlrange="0 2.4"/>
      </default>
    </default>
  </default>

  <worldbody>
    <body name="box" pos="0 0 0">
      <geom name="box" mass="0.4" size="0.10 0.075 0.15" type="box" material="object"/>
      <geom name="visual_box" mass="0" size="0.10 0.078 0.075" pos="0 0 0.075" type="box" rgba="1 0.83 0.5 1" contype="0" conaffinity="0"/>
      <site pos="0 0 0" name="site_box"/>
      <joint axis="1 0 0" name="slide_x" type="slide" range="-5 5"/>
      <joint axis="0 0 1" name="slide_z" type="slide" range="-5 5"/>
      <joint axis="0 -1 0" name="hinge_y" type="hinge"/>
    </body>

    <body name="robot_base" pos="0 0 0">
      <geom name="base_left" mass="1.0" pos="0.1 0 0" quat="0.5 0 0.5 0" size="0.05" type="sphere" material="grey"/>
      <geom name="base_right" mass="1.0" pos="-0.1 0 0" quat="0.5 0 0.5 0" size="0.05" type="sphere" material="grey"/>
      <body name="body_left_shoulder" pos="0.10 0 0">
        <geom name="left_shoulder_0" mass="0.5" pos="0.15 0 0" quat="0.5 0 0.5 0" size="0.05 0.05" type="capsule" material="black"/>
        <site pos="0.15 0 0" name="site_left_shoulder"/>
        <geom name="left_shoulder_1" mass="0.5" pos="0.30 0 0" quat="0.5 0 0.5 0" size="0.05" type="sphere" material="grey"/>
        <joint name="joint_left_shoulder" class="left_shoulder"/>
        <body name="body_left_elbow" pos="0.30 0 0">
          <geom name="left_elbow" mass="0.5" pos="0.15 0 0" quat="0.5 0 0.5 0" size="0.05 0.05" type="capsule" material="black"/>
          <site pos="0.15 0 0" name="site_left_elbow"/>
          <joint name="joint_left_elbow" class="left_elbow"/>
        </body>
      </body>
      <body name="body_right_shoulder" pos="-0.10 0 0">
        <geom name="right_shoulder_0" mass="0.5" pos="-0.15 0 0" quat="0.5 0 0.5 0" size="0.05 0.05" type="capsule" material="black"/>
        <site pos="-0.15 0 0" name="site_right_shoulder"/>
        <geom name="right_shoulder_1" mass="0.5" pos="-0.30 0 0" quat="0.5 0 0.5 0" size="0.05" type="sphere" material="grey"/>
        <joint name="joint_right_shoulder" class="right_shoulder"/>
        <body name="body_right_elbow" pos="-0.30 0 0">
          <geom name="right_elbow" mass="0.5" pos="-0.15 0 0" quat="0.5 0 0.5 0" size="0.05 0.05" type="capsule" material="black"/>
          <site pos="-0.15 0 0" name="site_right_elbow"/>
          <joint name="joint_right_elbow" class="right_elbow"/>
        </body>
      </body>
    </body>
  </worldbody>

  <keyframe>
    <!-- [object_xytheta arm_joint_angles] -->
    <key name="home" qpos="0 0 0  0 0 0 0" />
  </keyframe>

  <contact>
    <exclude body1="robot_base" body2="body_left_shoulder"/>
    <exclude body1="robot_base" body2="body_right_shoulder"/>
  </contact>

  <sensor>
    <framepos name="sensor_left_shoulder" objtype="site" objname="site_left_shoulder" reftype="site" refname="site_box"/>
    <framepos name="sensor_left_elbow" objtype="site" objname="site_left_elbow" reftype="site" refname="site_box"/>
    <framepos name="sensor_right_shoulder" objtype="site" objname="site_right_shoulder" reftype="site" refname="site_box"/>
    <framepos name="sensor_right_elbow" objtype="site" objname="site_right_elbow" reftype="site" refname="site_box"/>
  </sensor>

  <actuator>
    <position name="actuator_left_shoulder" joint="joint_left_shoulder" class="left_shoulder"/>
    <position name="actuator_left_elbow" joint="joint_left_elbow" class="left_elbow"/>
    <position name="actuator_right_shoulder" joint="joint_right_shoulder" class="right_shoulder"/>
    <position name="actuator_right_elbow" joint="joint_right_elbow" class="right_elbow"/>
  </actuator>
</mujoco>
