<mujoco model="spot_floating">
<!-- Copyright (c) 2023 Boston Dynamics AI Institute LLC. All rights reserved. -->
  <include file="spot_components/params_and_default.xml" />
  <include file="spot_components/assets.xml" />

  <worldbody>
    <geom name="ground" type="plane" size="2 2 0.01" friction="0.8" priority="5" material="blue_grid"/>

    <include file="../../components/objects/cartire.xml" />

    <body name="body" pos="0 0 0.49">
      <joint name="base_x" class="base" type="slide" axis="1 0 0" pos="0 0 0"/>
      <joint name="base_y" class="base" type="slide" axis="0 1 0" pos="0 0 0"/>
      <joint name="base_theta" class="base" type="hinge" axis="0 0 1" pos="0 0 0"/>
      <inertial mass="16.70765207" pos="0 0 -0.00496172" fullinertia="0.081543792 0.549231154 0.569454373 0 0 0"/>
      <geom name="body_0_visual" class="visual" mesh="body_0_visual" material="black"/>
      <geom name="body_1_visual" class="visual" mesh="body_1_visual" material="yellow"/>
      <!-- <geom name="body" type="mesh" mesh="body"/> -->
      <geom name="body" class="collision" type="box" size="0.42 0.11 0.08"/>
      <site name="site_body" pos="0 0 0" size="0.01"/>

      <include file="spot_components/fixed_legs.xml" />

      <include file="spot_components/arm.xml" />
    </body>
  </worldbody>

  <keyframe>
    <!-- mujoco q = [object_xyz, object_q, body_xytheta, arm_and_gripper_pos] -->
    <key name="home" qpos="0 0 0.275  0 0 0 0  0 0 0  0 0 0 0 0 0  0" />
  </keyframe>

  <actuator>
    <position name="act_0" joint="base_x" class="base"/>
    <position name="act_1" joint="base_y" class="base"/>
    <position name="act_2" joint="base_theta" class="base"/>
  </actuator>
  <include file="spot_components/actuators_sensors_floating.xml" />
  <contact>
    <exclude body1="outer_tire_collision" body2="body"/>
    <exclude body1="outer_tire_collision" body2="arm_link_sh0"/>
    <exclude body1="outer_tire_collision" body2="arm_link_sh1"/>
    <exclude body1="outer_tire_collision" body2="arm_link_el0"/>
    <exclude body1="outer_tire_collision" body2="arm_link_el1"/>
    <exclude body1="outer_tire_collision" body2="arm_link_wr0"/>
    <exclude body1="outer_tire_collision" body2="arm_link_wr1"/>
    <exclude body1="outer_tire_collision" body2="arm_link_fngr"/>
  </contact>
</mujoco>
