<mujoco model="spot_mink">
<!-- Copyright (c) 2024 Boston Dynamics AI Institute LLC. All rights reserved. -->
  <include file="../../components/spot/compiler.xml" />
  <include file="../../components/spot/defs.xml" />
  <include file="../../components/common/ground_defs.xml" />
  <include file="../../components/spot/base_defs.xml" />
  <include file="../../components/spot/arm_defs.xml" />

  <visual>
    <headlight diffuse="0.6 0.6 0.6" ambient="0.3 0.3 0.3" specular="0 0 0"/>
    <rgba haze="0.15 0.25 0.35 1"/>
    <global azimuth="100" elevation="-35"/>
  </visual>

  <worldbody>
    <light pos="0 0 1.5" dir="0 0 -1" directional="true"/>
    <geom name="ground" type="plane" size="10 10 0.01" friction="0.8" priority="5" material="blue_grid"/>

    <body name="ghost0" pos="0 0 0">
      <joint name="base_x" type="slide" axis="1 0 0"/>
      <inertial mass="1" pos="0 0 0" diaginertia="1 1 1"/>

      <body name="ghost1" pos="0 0 0">
        <joint name="base_y" type="slide" axis="0 1 0"/>
        <inertial mass="1" pos="0 0 0" diaginertia="1 1 1"/>

        <body name="ghost2" pos="0 0 0">
          <joint name="base_z" type="slide" axis="0 0 1" range="0.3 0.65"/>
          <inertial mass="1" pos="0 0 0" diaginertia="1 1 1"/>

          <body name="ghost3" pos="0 0 0">
            <joint name="base_roll" type="hinge" axis="1 0 0" range="-0.5 0.5"/>
            <inertial mass="1" pos="0 0 0" diaginertia="1 1 1"/>

            <body name="ghost4" pos="0 0 0">
              <joint name="base_pitch" type="hinge" axis="0 1 0" range="-0.5 0.5"/>
              <inertial mass="1" pos="0 0 0" diaginertia="1 1 1"/>

              <body name="body" pos="0 0 0">
                <joint name="base_yaw" type="hinge" axis="0 0 1"/>
                <inertial mass="16.70765207" pos="0 0 -0.00496172" fullinertia="0.081543792 0.549231154 0.569454373 0 0 0"/>
                <geom name="body_0_visual" class="visual" mesh="body_0_visual" material="black"/>
                <geom name="body_1_visual" class="visual" mesh="body_1_visual" material="yellow"/>
                <geom name="body" class="collision" type="box" size="0.42 0.11 0.08"/>
                <site name="site_body" pos="0 0 0.0" size="0.01"/>

                <include file="../../components/spot/arm.xml" />
              </body>
            </body>
          </body>
        </body>
      </body>
    </body>
  </worldbody>

  <worldbody>
    <body name="target" pos="0.5 0 .5" quat="0 1 0 0" mocap="true">
      <geom type="box" size=".05 .05 .05" contype="0" conaffinity="0" rgba=".6 .3 .3 .2"/>
    </body>
  </worldbody>

  <keyframe>
    <key name="home" qpos="0 0 0.55  0 0 0  0 -0.9 1.8 0 -0.9 0 0"/>
  </keyframe>
</mujoco>
