<mujoco model="spot_bimanual_stool">
<!-- Copyright (c) 2023 Boston Dynamics AI Institute LLC. All rights reserved. -->
  <include file="spot_components/params_and_default.xml" />
  <include file="spot_components/assets.xml" />

  <worldbody>
    <geom name="ground" type="plane" size="2 2 0.01" friction="0.7" priority="5" material="blue_grid"/>

    <include file="../../components/objects/stool.xml" />

    <body name="body_left" pos="0 1.15 0.49" euler="0 0 -1.57">
      <inertial mass="16.70765207" pos="0 0 -0.00496172" fullinertia="0.081543792 0.549231154 0.569454373 0 0 0"/>
      <geom name="body_0_visual_left" class="visual" mesh="body_0_visual" material="black"/>
      <geom name="body_1_visual_left" class="visual" mesh="body_1_visual" material="yellow"/>
      <!-- <geom name="body_left" type="mesh" mesh="body"/> -->
      <geom name="body_left" class="collision" type="box" size="0.42 0.11 0.08"/>
      <site name="site_body_left" pos="0 0 0" size="0.01"/>

      <body name="arm_link_sh0_left" pos="0.292 0 0.188" gravcomp="1">
        <joint name="arm_sh0_left" class="arm_sh0" type="hinge" axis="0 0 1" pos="0 0 0"/>
        <inertial mass="1.904699" fullinertia="0.008896 0.004922 0.0073030 0.000005 -0.000193 0.000033" pos="-0.008399 0.000272 -0.024603"/>
        <geom name="arm_link_sh0_visual_left" class="visual" mesh="arm_link_sh0_visual" material="black"/>
        <geom name="arm_link_sh0_base_left" class="collision" type="capsule" size="0.05 0.015" pos="0 0 -0.07"/>
        <geom name="arm_link_sh0_motor_left" class="collision" type="capsule" size="0.055 0.055" pos="-0.015 0 0" euler="1.57079632679 0 0"/>
        <!-- <geom name="arm_link_sh0_base_left" type="mesh" class="collision" mesh="arm_link_sh0_base"/> -->
        <!-- <geom name="arm_link_sh0_left_motor_left" type="mesh" class="collision" mesh="arm_link_sh0_left_motor"/> -->
        <!-- <geom name="arm_link_sh0_right_motor_left" type="mesh" class="collision" mesh="arm_link_sh0_right_motor"/> -->
        <site name="site_arm_link_sh0_left" pos="0 0 0" size="0.01"/>

        <body name="arm_link_sh1_left" pos="0 0 0" gravcomp="1">
          <joint name="arm_sh1_left" class="arm_sh1" type="hinge" axis="0 1 0" pos="0 0 0"/>
          <inertial mass="1.85701942" fullinertia="0.00261526 0.02703868 0.02819929 -0.00040406 0.00010019 0.00000547" pos="0.08084909 -0.00167243 0.00045644" />
          <geom name="arm_link_sh1_0_visual_left" class="visual" mesh="arm_link_sh1_0_visual" material="yellow"/>
          <geom name="arm_link_sh1_1_visual_left" class="visual" mesh="arm_link_sh1_1_visual" material="black"/>
          <geom name="arm_link_sh1_left" class="collision" type="capsule" size="0.04 0.175" pos="0.17 0 0" euler="0 1.57079632679 0"/>
          <!-- <geom name="arm_link_sh1_left" type="mesh" class="collision" mesh="arm_link_sh1"/> -->
          <site name="site_arm_link_sh1_left" pos="0 0 0" size="0.01"/>

          <body name="arm_link_el0_left" pos="0.3385 0 0" gravcomp="1">
            <joint name="arm_el0_left" class="arm_el0" type="hinge" axis="0 1 0" pos="0 0 0"/>
            <inertial mass="0.94831958" fullinertia="0.00175909 0.00269233 0.00202854 0.00006087  0.00092380 0.00005217" pos="0.04476621 -0.00271130 0.04991363" />
            <geom name="arm_link_el0_visual_left" class="visual" mesh="arm_link_el0_visual" material="black"/>
            <geom name="arm_link_el0_joint_left" class="collision" type="box" size="0.025 0.045 0.065" pos="0.02 0 0.04" euler= "0 0.5 0"/>
            <geom name="arm_link_el0_body_left" class="collision" type="capsule" size="0.045 0.025" pos="0.08 0 0.07" euler="0 1.57079632679 0"/>
            <!-- <geom name="arm_link_el0_left" type="mesh" class="collision" mesh="arm_link_el0"/> -->
            <site name="site_arm_link_el0_left" pos="0 0 0" size="0.01"/>

            <body name="arm_link_el1_left" pos="0.4033 0 0.075" gravcomp="1">
              <joint name="arm_el1_left" class="arm_el1" type="hinge" axis="1 0 0" pos="0 0 0"/>
              <inertial mass="1.01754820" fullinertia="0.00117710 0.01649389 0.01689901 -0.00260549 0.00000156 -0.00000287" pos="-0.16867073 -0.01616121 0.00001149" />
              <geom name="arm_link_el1_0_visual_left" class="visual" mesh="arm_link_el1_0_visual" material="yellow"/>
              <geom name="arm_link_el1_1_visual_left" class="visual" mesh="arm_link_el1_1_visual" material="black"/>
              <geom name="arm_link_el1_left" type="capsule" class="collision" size="0.035 0.095" pos="-0.15 0 0" euler="0 1.57079632679 0"/>
              <geom name="arm_link_el1_knob_left" type="sphere" class="collision" size="0.04" pos="0 -0.035 0"/>
              <!-- <geom name="arm_link_el1_main_left" type="mesh" class="collision" mesh="arm_link_el1_main"/> -->
              <!-- <geom name="arm_link_el1_lip_left" type="mesh" class="collision" mesh="arm_link_el1_lip"/> -->
              <site name="site_arm_link_el1_left" pos="0 0 0" size="0.01"/>

              <body name="arm_link_wr0_left" pos="0 0 0" gravcomp="1">
                <joint name="arm_wr0_left" class="arm_wr0" type="hinge" axis="0 1 0" pos="0 0 0"/>
                <inertial mass="0.58263740" fullinertia="0.00046738 0.00044968 0.00053616 0.00006957 0.00000040 0.00000016" pos="0.00952465 -0.01144406 0.00000186" />
                <geom name="arm_link_wr0_0_visual_left" class="visual" mesh="arm_link_wr0_0_visual" material="yellow"/>
                <geom name="arm_link_wr0_1_visual_left" class="visual" mesh="arm_link_wr0_1_visual" material="black"/>
                <geom name="arm_link_wr0_left" class="collision" type="capsule" size="0.035 0.04" pos="0.02 0 0" euler="0 1.57079632679 0"/>
                <!-- <geom name="arm_link_wr0_left" type="mesh" class="collision" mesh="arm_link_wr0"/> -->
                <site name="site_arm_link_wr0_left" pos="0 0 0" size="0.01"/>

                <body name="arm_link_wr1_left" pos="0 0 0" gravcomp="1">
                  <joint name="arm_wr1_left" class="arm_wr1" type="hinge" axis="1 0 0" pos="0 0 0"/>
                  <inertial mass="0.93335298" fullinertia="0.00098836 0.00197018 0.00165791 -0.00000126 -0.00036919 -0.00000074" pos="0.09751283 0.00009265 -0.01120523" />
                  <geom name="arm_link_wr1_0_visual_left" class="visual" mesh="arm_link_wr1_0_visual" material="yellow"/>
                  <geom name="arm_link_wr1_1_visual_left" class="visual" mesh="arm_link_wr1_1_visual" material="black"/>
                  <geom name="arm_link_wr1_left" class="collision" type="box" size="0.03 0.04 0.0475" pos="0.11 0 -0.01" />
                  <geom name="bottom_jaw_left" class="collision" type="box" size="0.03 0.025 0.01" pos="0.17 0 -0.0475" />
                  <geom name="front_jaw_left" class="collision" type="box" size="0.016 0.015 0.01" pos="0.215 0 -0.0475" />
                  <geom name="front_jaw_tooth_left" class="collision" type="box" size="0.005 0.01 0.005" pos="0.224 0 -0.039" euler="0 1 0"/>
                  <!-- <geom name="arm_link_wr1_left" type="mesh" class="collision" mesh="arm_link_wr1"/> -->
                  <!-- <geom name="front_jaw_left" type="mesh" class="collision" mesh="front_jaw"/> -->
                  <!-- <geom name="middle_jaw_left" type="mesh" class="collision" mesh="middle_jaw"/> -->
                  <!-- <geom name="jaw_tooth_left" type="mesh" class="collision" mesh="jaw_tooth"/> -->
                  <site name="site_arm_link_wr1_left" pos="0 0 0" size="0.01"/>

                  <body name="arm_link_fngr_left" pos="0.11745 0.0 0.014820" gravcomp="1">
                    <joint name="arm_f1x_left" class="arm_f1x" type="hinge" axis="0 1 0" pos="0 0 0"/>
                    <inertial mass="0.22383315" fullinertia="0.00025226 0.00048453 0.00059145 -0.00000536 -0.00015067 0.00000184" pos="0.03565178 0.00067200 -0.01227516" />
                    <geom name="arm_link_fngr_0_visual_left" class="visual" mesh="arm_link_fngr_0_visual" material="yellow"/>
                    <geom name="arm_link_fngr_1_visual_left" class="visual" mesh="arm_link_fngr_1_visual" material="black"/>
                    <geom name="left_jaw_left" type="capsule" class="collision" size="0.015 0.06" pos="0.057 0.023 -0.023" euler="-0.45 2.0 0"/>
                    <geom name="right_jaw_left" type="capsule" class="collision" size="0.015 0.06" pos="0.057 -0.023 -0.023" euler="0.45 2.0 0"/>
                    <!-- <geom name="left_hinge_left" type="mesh" class="collision" mesh="left_hinge"/> -->
                    <!-- <geom name="left_finger_left" type="mesh" class="collision" mesh="left_finger"/> -->
                    <!-- <geom name="left_tooth_left" type="mesh" class="collision" mesh="left_tooth"/> -->
                    <!-- <geom name="right_hinge_left" type="mesh" class="collision" mesh="right_hinge"/> -->
                    <!-- <geom name="right_finger_left" type="mesh" class="collision" mesh="right_finger"/> -->
                    <!-- <geom name="right_tooth_left" type="mesh" class="collision" mesh="right_tooth"/> -->
                    <site name="site_arm_link_fngr_left" pos="0 0 0" size="0.01"/>
                  </body>
                </body>
              </body>
            </body>
          </body>
        </body>
      </body>
    </body>
    <body name="body_right" pos="0 -1.15 0.49" euler="0 0 1.57">
      <inertial mass="16.70765207" pos="0 0 -0.00496172" fullinertia="0.081543792 0.549231154 0.569454373 0 0 0"/>
      <geom name="body_0_visual_right" class="visual" mesh="body_0_visual" material="black"/>
      <geom name="body_1_visual_right" class="visual" mesh="body_1_visual" material="yellow"/>
      <!-- <geom name="body_right" type="mesh" mesh="body"/> -->
      <geom name="body_right" class="collision" type="box" size="0.42 0.11 0.08"/>
      <site name="site_body_right" pos="0 0 0" size="0.01"/>

      <body name="arm_link_sh0_right" pos="0.292 0 0.188" gravcomp="1">
        <joint name="arm_sh0_right" class="arm_sh0" type="hinge" axis="0 0 1" pos="0 0 0"/>
        <inertial mass="1.904699" fullinertia="0.008896 0.004922 0.0073030 0.000005 -0.000193 0.000033" pos="-0.008399 0.000272 -0.024603"/>
        <geom name="arm_link_sh0_visual_right" class="visual" mesh="arm_link_sh0_visual" material="black"/>
        <geom name="arm_link_sh0_base_right" class="collision" type="capsule" size="0.05 0.015" pos="0 0 -0.07"/>
        <geom name="arm_link_sh0_motor_right" class="collision" type="capsule" size="0.055 0.055" pos="-0.015 0 0" euler="1.57079632679 0 0"/>
        <!-- <geom name="arm_link_sh0_base_right" type="mesh" class="collision" mesh="arm_link_sh0_base"/> -->
        <!-- <geom name="arm_link_sh0_left_motor_right" type="mesh" class="collision" mesh="arm_link_sh0_left_motor"/> -->
        <!-- <geom name="arm_link_sh0_right_motor_right" type="mesh" class="collision" mesh="arm_link_sh0_right_motor"/> -->
        <site name="site_arm_link_sh0_right" pos="0 0 0" size="0.01"/>

        <body name="arm_link_sh1_right" pos="0 0 0" gravcomp="1">
          <joint name="arm_sh1_right" class="arm_sh1" type="hinge" axis="0 1 0" pos="0 0 0"/>
          <inertial mass="1.85701942" fullinertia="0.00261526 0.02703868 0.02819929 -0.00040406 0.00010019 0.00000547" pos="0.08084909 -0.00167243 0.00045644" />
          <geom name="arm_link_sh1_0_visual_right" class="visual" mesh="arm_link_sh1_0_visual" material="yellow"/>
          <geom name="arm_link_sh1_1_visual_right" class="visual" mesh="arm_link_sh1_1_visual" material="black"/>
          <geom name="arm_link_sh1_right" class="collision" type="capsule" size="0.04 0.175" pos="0.17 0 0" euler="0 1.57079632679 0"/>
          <!-- <geom name="arm_link_sh1_right" type="mesh" class="collision" mesh="arm_link_sh1"/> -->
          <site name="site_arm_link_sh1_right" pos="0 0 0" size="0.01"/>

          <body name="arm_link_el0_right" pos="0.3385 0 0" gravcomp="1">
            <joint name="arm_el0_right" class="arm_el0" type="hinge" axis="0 1 0" pos="0 0 0"/>
            <inertial mass="0.94831958" fullinertia="0.00175909 0.00269233 0.00202854 0.00006087  0.00092380 0.00005217" pos="0.04476621 -0.00271130 0.04991363" />
            <geom name="arm_link_el0_visual_right" class="visual" mesh="arm_link_el0_visual" material="black"/>
            <geom name="arm_link_el0_joint_right" class="collision" type="box" size="0.025 0.045 0.065" pos="0.02 0 0.04" euler= "0 0.5 0"/>
            <geom name="arm_link_el0_body_right" class="collision" type="capsule" size="0.045 0.025" pos="0.08 0 0.07" euler="0 1.57079632679 0"/>
            <!-- <geom name="arm_link_el0_right" type="mesh" class="collision" mesh="arm_link_el0"/> -->
            <site name="site_arm_link_el0_right" pos="0 0 0" size="0.01"/>

            <body name="arm_link_el1_right" pos="0.4033 0 0.075" gravcomp="1">
              <joint name="arm_el1_right" class="arm_el1" type="hinge" axis="1 0 0" pos="0 0 0"/>
              <inertial mass="1.01754820" fullinertia="0.00117710 0.01649389 0.01689901 -0.00260549 0.00000156 -0.00000287" pos="-0.16867073 -0.01616121 0.00001149" />
              <geom name="arm_link_el1_0_visual_right" class="visual" mesh="arm_link_el1_0_visual" material="yellow"/>
              <geom name="arm_link_el1_1_visual_right" class="visual" mesh="arm_link_el1_1_visual" material="black"/>
              <geom name="arm_link_el1_right" type="capsule" class="collision" size="0.035 0.095" pos="-0.15 0 0" euler="0 1.57079632679 0"/>
              <geom name="arm_link_el1_knob_right" type="sphere" class="collision" size="0.04" pos="0 -0.035 0"/>
              <!-- <geom name="arm_link_el1_main_right" type="mesh" class="collision" mesh="arm_link_el1_main"/> -->
              <!-- <geom name="arm_link_el1_lip_right" type="mesh" class="collision" mesh="arm_link_el1_lip"/> -->
              <site name="site_arm_link_el1_right" pos="0 0 0" size="0.01"/>

              <body name="arm_link_wr0_right" pos="0 0 0" gravcomp="1">
                <joint name="arm_wr0_right" class="arm_wr0" type="hinge" axis="0 1 0" pos="0 0 0"/>
                <inertial mass="0.58263740" fullinertia="0.00046738 0.00044968 0.00053616 0.00006957 0.00000040 0.00000016" pos="0.00952465 -0.01144406 0.00000186" />
                <geom name="arm_link_wr0_0_visual_right" class="visual" mesh="arm_link_wr0_0_visual" material="yellow"/>
                <geom name="arm_link_wr0_1_visual_right" class="visual" mesh="arm_link_wr0_1_visual" material="black"/>
                <geom name="arm_link_wr0_right" class="collision" type="capsule" size="0.035 0.04" pos="0.02 0 0" euler="0 1.57079632679 0"/>
                <!-- <geom name="arm_link_wr0_right" type="mesh" class="collision" mesh="arm_link_wr0"/> -->
                <site name="site_arm_link_wr0_right" pos="0 0 0" size="0.01"/>

                <body name="arm_link_wr1_right" pos="0 0 0" gravcomp="1">
                  <joint name="arm_wr1_right" class="arm_wr1" type="hinge" axis="1 0 0" pos="0 0 0"/>
                  <inertial mass="0.93335298" fullinertia="0.00098836 0.00197018 0.00165791 -0.00000126 -0.00036919 -0.00000074" pos="0.09751283 0.00009265 -0.01120523" />
                  <geom name="arm_link_wr1_0_visual_right" class="visual" mesh="arm_link_wr1_0_visual" material="yellow"/>
                  <geom name="arm_link_wr1_1_visual_right" class="visual" mesh="arm_link_wr1_1_visual" material="black"/>
                  <geom name="arm_link_wr1_right" class="collision" type="box" size="0.03 0.04 0.0475" pos="0.11 0 -0.01" />
                  <geom name="bottom_jaw_right" class="collision" type="box" size="0.03 0.025 0.01" pos="0.17 0 -0.0475" />
                  <geom name="front_jaw_right" class="collision" type="box" size="0.016 0.015 0.01" pos="0.215 0 -0.0475" />
                  <geom name="front_jaw_tooth_right" class="collision" type="box" size="0.005 0.01 0.005" pos="0.224 0 -0.039" euler="0 1 0"/>
                  <!-- <geom name="arm_link_wr1_right" type="mesh" class="collision" mesh="arm_link_wr1"/> -->
                  <!-- <geom name="front_jaw_right" type="mesh" class="collision" mesh="front_jaw"/> -->
                  <!-- <geom name="middle_jaw_right" type="mesh" class="collision" mesh="middle_jaw"/> -->
                  <!-- <geom name="jaw_tooth_right" type="mesh" class="collision" mesh="jaw_tooth"/> -->
                  <site name="site_arm_link_wr1_right" pos="0 0 0" size="0.01"/>

                  <body name="arm_link_fngr_right" pos="0.11745 0.0 0.014820" gravcomp="1">
                    <joint name="arm_f1x_right" class="arm_f1x" type="hinge" axis="0 1 0" pos="0 0 0"/>
                    <inertial mass="0.22383315" fullinertia="0.00025226 0.00048453 0.00059145 -0.00000536 -0.00015067 0.00000184" pos="0.03565178 0.00067200 -0.01227516" />
                    <geom name="arm_link_fngr_0_visual_right" class="visual" mesh="arm_link_fngr_0_visual" material="yellow"/>
                    <geom name="arm_link_fngr_1_visual_right" class="visual" mesh="arm_link_fngr_1_visual" material="black"/>
                    <geom name="left_jaw_right" type="capsule" class="collision" size="0.015 0.06" pos="0.057 0.023 -0.023" euler="-0.45 2.0 0"/>
                    <geom name="right_jaw_right" type="capsule" class="collision" size="0.015 0.06" pos="0.057 -0.023 -0.023" euler="0.45 2.0 0"/>
                    <!-- <geom name="left_hinge_right" type="mesh" class="collision" mesh="left_hinge"/> -->
                    <!-- <geom name="left_finger_right" type="mesh" class="collision" mesh="left_finger"/> -->
                    <!-- <geom name="left_tooth_right" type="mesh" class="collision" mesh="left_tooth"/> -->
                    <!-- <geom name="right_hinge_right" type="mesh" class="collision" mesh="right_hinge"/> -->
                    <!-- <geom name="right_finger_right" type="mesh" class="collision" mesh="right_finger"/> -->
                    <!-- <geom name="right_tooth_right" type="mesh" class="collision" mesh="right_tooth"/> -->
                    <site name="site_arm_link_fngr_right" pos="0 0 0" size="0.01"/>
                  </body>
                </body>
              </body>
            </body>
          </body>
        </body>
      </body>
    </body>
  </worldbody>

  <!-- TODO for some reason necessary here but not for floating spot-->
  <contact>
    <exclude body1="body_left" body2="arm_link_sh0_left"/>
    <exclude body1="body_right" body2="arm_link_sh0_right"/>
  </contact>

  <keyframe>
    <!-- mujoco q = [object_xyz, object_q, arm_and_gripper_pos_left, arm_and_gripper_pos_right] -->
    <key name="home" qpos="0 0 0.275  0 0 0 0  0 0 0 0 0 0  0  0 0 0 0 0 0  0" />
  </keyframe>

  <actuator>
    <position name="act_1_left" joint="arm_sh0_left" class="arm_sh0"/>
    <position name="act_2_left" joint="arm_sh1_left" class="arm_sh1"/>
    <position name="act_3_left" joint="arm_el0_left" class="arm_el0"/>
    <position name="act_4_left" joint="arm_el1_left" class="arm_el1"/>
    <position name="act_5_left" joint="arm_wr0_left" class="arm_wr0"/>
    <position name="act_6_left" joint="arm_wr1_left" class="arm_wr1"/>
    <position name="act_7_left" joint="arm_f1x_left" class="arm_f1x"/>

    <position name="act_1_right" joint="arm_sh0_right" class="arm_sh0"/>
    <position name="act_2_right" joint="arm_sh1_right" class="arm_sh1"/>
    <position name="act_3_right" joint="arm_el0_right" class="arm_el0"/>
    <position name="act_4_right" joint="arm_el1_right" class="arm_el1"/>
    <position name="act_5_right" joint="arm_wr0_right" class="arm_wr0"/>
    <position name="act_6_right" joint="arm_wr1_right" class="arm_wr1"/>
    <position name="act_7_right" joint="arm_f1x_right" class="arm_f1x"/>
  </actuator>

  <sensor>
    <framepos name="sensor_body_left" objtype="site" objname="site_body_left" reftype="site" refname="site_object" />
    <framepos name="sensor_arm_link_sh0_left" objtype="site" objname="site_arm_link_sh0_left" reftype="site" refname="site_object" />
    <framepos name="sensor_arm_link_sh1_left" objtype="site" objname="site_arm_link_sh1_left" reftype="site" refname="site_object" />
    <framepos name="sensor_arm_link_el0_left" objtype="site" objname="site_arm_link_el0_left" reftype="site" refname="site_object" />
    <framepos name="sensor_arm_link_el1_left" objtype="site" objname="site_arm_link_el1_left" reftype="site" refname="site_object" />
    <framepos name="sensor_arm_link_wr0_left" objtype="site" objname="site_arm_link_wr0_left" reftype="site" refname="site_object" />
    <framepos name="sensor_arm_link_wr1_left" objtype="site" objname="site_arm_link_wr1_left" reftype="site" refname="site_object" />
    <framepos name="sensor_arm_link_fngr_left" objtype="site" objname="site_arm_link_fngr_left" reftype="site" refname="site_object" />

    <framepos name="sensor_body_right" objtype="site" objname="site_body_right" reftype="site" refname="site_object" />
    <framepos name="sensor_arm_link_sh0_right" objtype="site" objname="site_arm_link_sh0_right" reftype="site" refname="site_object" />
    <framepos name="sensor_arm_link_sh1_right" objtype="site" objname="site_arm_link_sh1_right" reftype="site" refname="site_object" />
    <framepos name="sensor_arm_link_el0_right" objtype="site" objname="site_arm_link_el0_right" reftype="site" refname="site_object" />
    <framepos name="sensor_arm_link_el1_right" objtype="site" objname="site_arm_link_el1_right" reftype="site" refname="site_object" />
    <framepos name="sensor_arm_link_wr0_right" objtype="site" objname="site_arm_link_wr0_right" reftype="site" refname="site_object" />
    <framepos name="sensor_arm_link_wr1_right" objtype="site" objname="site_arm_link_wr1_right" reftype="site" refname="site_object" />
    <framepos name="sensor_arm_link_fngr_right" objtype="site" objname="site_arm_link_fngr_right" reftype="site" refname="site_object" />
  </sensor>
</mujoco>
